概要
* [例外処理について](#例外処理について)
* [例外処理の種類](#例外処理の種類)
  * [例外とエラーの継承関係](#例外とエラーの継承関係)
* [throw と throws](#throw-と-throws)
  * [故意に例外をスローしてみた【同クラス】](#故意に例外をスローしてみた同クラス)
  * [故意に例外をスローしてみた【別クラス】](#故意に例外をスローしてみた別クラス)
* [例外オブジェクトメソッド](#例外オブジェクトメソッド)
  * [スタックトレースを出力](#スタックトレースを出力)
  * [スタックトレースを配列で取得](#スタックトレースを配列で取得)
  * [例外の詳細なメッセージを取得](#例外の詳細なメッセージを取得)
  * [例外のクラス名とメッセージを組み合わせた文字列](#例外のクラス名とメッセージを組み合わせた文字列)
  * [例外の原因となった元の例外](#例外の原因となった元の例外)
  * [例外の原因となる例外を後から設定する](#例外の原因となる例外を後から設定する)
  * [スタックトレースをカスタマイズして設定する](#スタックトレースをカスタマイズして設定する)
  * [スタックトレース情報を現在のスレッドの情報で更新する](#スタックトレース情報を現在のスレッドの情報で更新する)
* [その他、try-with-resources](#その他try-with-resources)

***************************************************************************
## 例外処理について
* 予期しない`エラー`や`異常状態`を`例外（Exception）`として扱う
* 基本の構造は`try`-`catch`-`finally`を使う
```Java
try {
    // エラーが発生する可能性があるコード
} catch (例外型 変数名) {
// } catch (例外型 変数名 | 例外型 変数名) { // 複数の例外を処理したい場合
    // 例外が発生した際に実行する処理
} finally {
    // 例外が発生したかに関わらず必ず実行される処理
    // finallyの記述は場合によっては必須ではない
}
```

## 例外処理の種類
1. チェック例外 (Checked Exception)
    * `コンパイル時`にチェックされる例外。未処理の場合、コンパイルエラー。IOException や SQLExceptionなど
    * try-catchまたはthrows処理が必須
    * 主な用途：外部要因によるエラー（例: 入出力、ネットワーク）

| 例外クラス | 発生状況の例 |
| --- | --- |
| IOException | 入出力エラー<br>ファイルが見つからない、または読み書きに失敗した場合 |
| FileNotFoundException | 指定されたファイルが存在しない場合に発生 |
| SQLException | データベース接続やSQLクエリで問題が発生した場合 |
| ClassNotFoundException | クラスが動的にロードできなかった場合 |
| InterruptedException | スレッドが割り込まれた場合 |
| MalformedURLException | 無効なURLが指定された場合 |
| CloneNotSupportedException | クローン操作がサポートされていないオブジェクトに対して行われた場合 |
| InstantiationException | 抽象クラスやインターフェースのインスタンスを作成しようとした場合 |
| ParseException | 解析中に予想外のエラーが発生した場合 |

2. 非チェック例外（Unchecked Exception）
    * 実行時例外 (Unchecked Exception)とErrorを継承する例外
    * `実行時`に発生する例外。コンパイル時には検出されない。NullPointerException や ArrayIndexOutOfBoundsException など
    * 処理は任意（強制されない）
    * プログラムのバグや設計ミスによるエラー

| 例外クラス | 発生状況の例 |
| --- | --- |
| NullPointerException | null参照にアクセスした場合 |
| ArrayIndexOutOfBoundsException | 配列の範囲外にアクセスした場合 |
| ArithmeticException | 数学演算エラー（例: 0による除算） |
| IllegalArgumentException | メソッドに無効な引数が渡された場合 |
| NumberFormatException | 数値として解析できない文字列を処理した場合 |
| ClassCastException | 無効な型キャストを試みた場合 |
| IllegalStateException | オブジェクトが不正な状態で操作された場合 |
| UnsupportedOperationException | サポートされていない操作を実行しようとした場合 |

3. エラー (Error)
    * `JVM自体に関連する`重大なエラー（例: OutOfMemoryError）
    * 基本的にプログラムで処理しない
    * 例：無限生成ループに陥る/メモリ不足

| エラークラス | 発生状況の例 |
| --- | --- |
| OutOfMemoryError | ヒープ領域が不足したときに発生<br>例: メモリ不足でオブジェクトを作成できない |
| StackOverflowError | スタックが限界を超えた場合に発生<br>例: 無限再帰 |
| VirtualMachineError | JVMが正常に動作できない場合に発生<br>例: InternalError や OutOfMemoryError |

### 例外とエラーの継承関係
`Throwable`はJavaのすべての例外とエラーのスーパークラス
```
java.lang.Throwable
├── java.lang.Error (非チェック例外)【JVMの重大なエラー】
│   ├── OutOfMemoryError【ヒープ領域が不足】
│   ├── StackOverflowError【無限再帰などでスタック限界超過】
│   ├── InternalError【JVMの内部エラー】
│   ├── AssertionError【assert文が失敗した場合】
│   ├── VirtualMachineError【JVMの動作不能状態】
│   │   ├── OutOfMemoryError【メモリ不足時】
│   │   ├── StackOverflowError【再帰や無限ループでスタック超過】
│   │   └── UnknownError【未知の深刻なエラー】
│   └── LinkageError【クラスのリンク中にエラー発生】
│       ├── NoClassDefFoundError【クラスが見つからない】
│       ├── ClassFormatError【クラスファイルが無効な形式】
│       └── UnsatisfiedLinkError【ネイティブライブラリがリンクできない】
│
└── java.lang.Exception (チェック例外)【通常のプログラムで処理可能】
    ├── IOException【入出力エラー】
    │   ├── FileNotFoundException【ファイルが見つからない】
    │   ├── EOFException【ファイルの終端に到達】
    │   ├── SocketException【ネットワークソケットエラー】
    │   └── MalformedURLException【URLが無効】
    │
    ├── SQLException【データベース接続エラー】
    │   ├── SQLTimeoutException【SQL操作のタイムアウト】
    │   └── BatchUpdateException【バッチ更新中のエラー】
    │
    ├── ClassNotFoundException【クラスが見つからない】
    ├── InterruptedException【スレッドが割り込まれた】
    ├── ParseException【文字列の解析エラー】
    ├── CloneNotSupportedException【クローン操作がサポートされていない】
    ├── InstantiationException【抽象クラスやインターフェースのインスタンス生成失敗】
    └── InvocationTargetException【リフレクションAPI中の例外】
    │
    ├── java.lang.RuntimeException (非チェック例外)【プログラムの設計ミス】
    │   ├── NullPointerException【null参照にアクセス】
    │   ├── IndexOutOfBoundsException【インデックス範囲外アクセス】
    │   │   ├── ArrayIndexOutOfBoundsException【配列の範囲外アクセス】
    │   │   └── StringIndexOutOfBoundsException【文字列の範囲外アクセス】
    │   ├── ArithmeticException【数学演算エラー（例: 0除算）】
    │   ├── IllegalArgumentException【無効な引数】
    │   │   └── NumberFormatException【数値変換エラー（文字列→数値失敗）】
    │   ├── ClassCastException【無効な型キャスト】
    │   ├── IllegalStateException【オブジェクトの状態が不正】
    │   ├── UnsupportedOperationException【サポートされていない操作】
    │   └── ConcurrentModificationException【コレクションの不正な変更】
    │
    ├── IllegalThreadStateException【スレッド操作が不正】
    └── SecurityException【セキュリティ違反】
```

***************************************************************************
## throw と throws
* **throw**
  * 明示的に例外をスローする
  * `例外インスタンス`を生成し、throwキーワードに与える
* **throws**  
  * `メソッド宣言で`スローする可能性のある例外を指定します
  * `チェック例外`を発生させる場合はメソッドの定義にthrowsキーワードを使用し明記
  * `非チェック例外`の場合、throws を明記する必要はないが、他の開発者に意図を伝えるために書いておくことには便利

### 故意に例外をスローしてみた【同クラス】
```Java
public class Main {
    public static void main(String... args) {
        String s = null;
        try {
            test(s);
        } catch (Exception e) {
            e.printStackTrace(); // 標準エラー出力、発生した例外の種類、例外が発生した場所
            System.err.println("実行時エラーが発生しました。" + e.getMessage()); // outではなくerrにすると実行時エラータグに記録される
        }
    }

    static void test(String s) throws Exception{
        try {
            if (s == null) {
                throw new Exception("引数がnullです"); //　java.lang.Exception: 引数がnullです　と表示される。指定しなくても大丈夫
            }
        } catch (Exception e) {
            System.err.println("throwした例外をキャッチ");
            throw e; // 例外の再スローは、例外をキャッチした場所では処理できないが、
            // 呼び出し元で処理する必要がある場合に使います。
            // 再スローしないと、その時点で例外処理が終了してしまい、
            // 上位メソッドでは例外が処理されなくなります。
            // この場合、書かないと【"throwした例外をキャッチ"】のエラーメッセージのみが表示される
        }
        System.out.println(s);
    }
} 
```
今回の例では、エラーメッセージに以下内容は出力される  
なお、2-4行目の内容は`e.printStackTrace();`が返した内容となる
```
throwした例外をキャッチ
java.lang.Exception: 引数がnullです
	at Main.test(Main.java:15)
	at Main.main(Main.java:5)
実行時エラーが発生しました。引数がnullです
```

### 故意に例外をスローしてみた【別クラス】
```Java
class CustomException extends Exception {
    public CustomException(String message) {
        super(message);
    }
}

public class Main {
    public static void main(String[] args) {
        try {
            throw new CustomException("独自の例外が発生しました。");
        } catch (CustomException e) {
            System.err.println(e.getMessage());
        }
    }
}
```
今回の例では、エラーメッセージに以下内容は出力される
```
独自の例外が発生しました。
```

***************************************************************************
## 例外オブジェクトメソッド
便宜上、以下内容は`Exception e`との変数名で説明する

### スタックトレースを出力
e.printStackTrace()  
※ 標準エラー出力に出力する
出力内容：
* 例外の完全修飾クラス名（例: java.lang.Exception）
* 例外メッセージ（例: 引数がnullです）
* スタックトレースの各行（例: at Main.test(Main.java:18)）
```Java
try {
    throw new Exception("テスト例外");
} catch (Exception e) {
    e.printStackTrace();
}
```
出力内容：
```Java
java.lang.Exception: テスト例外
	at Main.main(Main.java:4)
```


### スタックトレースを配列で取得
e.getStackTrace()  
出力内容：  
* 例外メッセージや例外クラス名は含まれず、純粋にスタックトレース（StackTraceElement オブジェクト）だけが取得する  
※ 大量の例外が発生する場合にはパフォーマンスの問題になる可能性があるため、必要な場合に限定して利用しよう
```Java
try {
    throw new Exception("テスト例外");
} catch (Exception e) {
    for (StackTraceElement element : e.getStackTrace()) {
        System.out.println("クラス名: " + element.getClassName());
        System.out.println("メソッド名: " + element.getMethodName());
        System.out.println("ファイル名: " + element.getFileName());
        System.out.println("行番号: " + element.getLineNumber());
    }
}
```
出力内容：
```
クラス名: Main
メソッド名: main
ファイル名: Main.java
行番号: 4
```

### 例外の詳細なメッセージを取得
e.getMessage()  
※ 例外インスタンス生成時に渡した文字列が対象
```Java
try {
    throw new Exception("テスト例外");
} catch (Exception e) {
    System.err.println(e.getMessage());
}
```
出力内容
```
テスト例外
```

### 例外のクラス名とメッセージを組み合わせた文字列
e.toString()
```Java
try {
    throw new Exception("例外の詳細メッセージ");
} catch (Exception e) {
    System.err.println(e.toString());
}
```
出力内容：
```
java.lang.Exception: 例外の詳細メッセージ
```

### 例外の原因となった元の例外
e.getCause()
```Java
try {
    throw new Exception("トップレベルの例外", new NullPointerException("原因例外"));
} catch (Exception e) {
    System.out.println("原因: " + e.getCause());
}
```
出力内容：
```
原因: java.lang.NullPointerException: 原因例外
```

### 例外の原因となる例外を後から設定する
e.intitCause(Throwable cause)
* 例外チェーンを作成する場合に利用
* エラーの起因関係を明確にすることで、デバッグやログ解析がしやすくなる
```Java
try {
    throw new Exception("原因となる例外");
} catch (Exception e) {
    Exception customException = new Exception("カスタム例外");
    customException.initCause(e); // e を原因として設定
    customException.printStackTrace();
}
```
出力内容
```
java.lang.Exception: カスタム例外
	at Main.main(Main.java:6)
Caused by: java.lang.Exception: 原因となる例外
	at Main.main(Main.java:4)
```

### スタックトレースをカスタマイズして設定する
e.setStackTrace(StackTraceElement[] stackTrace)
* 特殊なシナリオで、例外をカスタマイズしたい場合に使用
* 機密情報を含む実際のスタックトレースを隠したり、モックデータとして使用したりする
* デバッグ時に有用なことがあるが、使用は慎重に

```Java
try {
    throw new Exception("オリジナル例外");
} catch (Exception e) {
    StackTraceElement[] customStackTrace = new StackTraceElement[] {
        new StackTraceElement("FakeClass", "fakeMethod", "FakeFile.java", 123)
    };
    e.setStackTrace(customStackTrace);
    e.printStackTrace();
}
```
出力内容
```
java.lang.Exception: オリジナル例外
	at FakeClass.fakeMethod(FakeFile.java:123)
```

### スタックトレース情報を現在のスレッドの情報で更新する
e.fillInStackTrace()	
```Java
try {
    Exception ex = new Exception("例外A");
    throw (Exception) ex.fillInStackTrace();
} catch (Exception e) {
    e.printStackTrace();
}
```
出力内容：
```
java.lang.Exception: 例外A
	at Main.main(Main.java:5)
```


***************************************************************************
## その他、try-with-resources
* リソースを自動的に閉じる try-with-resources構文
* try 内で定義されたリソース（例: BufferedReader）は、try ブロックが終了したときに自動的に閉じられる
* リソースクラスは AutoCloseable インターフェースを実装している必要がある
```Java
import java.io.*;

public class Main {
    public static void main(String[] args) {
        try (BufferedReader br = new BufferedReader(new FileReader("example.txt"))) {
            System.out.println(br.readLine());
        } catch (IOException e) {
            e.printStackTrace();
        }
    }
}
```
