概要
* [例外処理について](#例外処理について)
* [try-catch-finally](#try-catch-finally)
    * [try](#try)
    * [catch](#catch)
    * [finally](#finally)
* [例外のスロー](#例外のスロー)
* [例外の再スロー](#例外の再スロー)
    * [throwをそのまま使う](#throwをそのまま使う)
    * [新しい例外をスローする](#新しい例外をスローする)
    * [ユーザー定義の例外](#ユーザー定義の例外)
    * [例外フィルター](#例外フィルター)
* [例外処理の種類](#例外処理の種類)
    * [例外とエラーの継承関係](#例外とエラーの継承関係)
* [例外処理のベストプラクティス](#例外処理のベストプラクティス)
* [非同期メソッドの例外処理](#非同期メソッドの例外処理)
    * [async メソッド内での例外](#asyncメソッド内での例外)
    * [Task.Wait() や Task.Result の使用](#taskwait-や-taskresult-の使用)
* [グローバル例外処理](#グローバル例外処理)
    * [コンソールアプリの場合](#コンソールアプリの場合)
    * [WPFアプリの場合](#WPFアプリの場合)
* [ロギングツールの利用](#ロギングツールの利用)
* [例外処理を使わない設計の検討](#例外処理を使わない設計の検討)

***************************************************************************
## 例外処理について
* 予期しない`エラー`や`異常状態`を`例外（Exception）`として扱う
* 基本の構造は`try`-`catch`-`finally`を使う
```Java
try {
    // エラーが発生する可能性があるコード
} catch (例外型 変数名) {
    // 例外が発生した際に実行する処理
} finally {
    // 例外が発生したかに関わらず必ず実行される処理
    // finallyは省略可能
}
```

例外処理実例
```C#
using System;

class Program
{
    static void Main()
    {
        try
        {
            // エラーが発生する可能性があるコード
            int[] numbers = { 1, 2, 3 };
            Console.WriteLine("3番目の要素: " + numbers[2]);
            
            // インデックス範囲外にアクセス
            Console.WriteLine("5番目の要素: " + numbers[4]);
        }
        catch (IndexOutOfRangeException ex)
        {
            // 例外が発生した際に実行される処理
            Console.WriteLine("エラー: 配列のインデックスが範囲外です。");
            Console.WriteLine($"詳細: {ex.Message}");
        }
        catch (Exception ex)
        {
            // その他の例外をキャッチする
            Console.WriteLine("予期しないエラーが発生しました。");
            Console.WriteLine($"詳細: {ex.Message}");
        }
        finally
        {
            // 例外が発生したかに関わらず必ず実行される処理
            Console.WriteLine("プログラム終了時のクリーンアップ処理を行います。");
        }
    }
}
```
上記例の出力内容：
```
3番目の要素: 3
エラー: 配列のインデックスが範囲外です。
詳細: Index was outside the bounds of the array.
プログラム終了時のクリーンアップ処理を行います。
```

## try-catch-finally
### try
* エラーが発生する可能性があるコードを囲む部分
* ここで例外が発生すると、残りのコードはスキップされ、対応するcatchブロックが実行される

### catch
* 特定の例外を捕捉し、適切な庶路を行う部分
* 例外の種類ごとに複数の`catch`ブロックを用意できる
* 最も適切の例外が捕捉される
```C#
catch (ArgumentNullException ex)
{
    Console.WriteLine($"引数がnullです: {ex.Message}");
}
catch (Exception ex)
{
    Console.WriteLine($"エラーが発生しました: {ex.Message}");
}
```

### finally
* tryやcatchの後に記述する
* 例外の有無に関わらず必ず実行されるコード
* **リソースの解放**や**後処理**に使う  

※ 注意点 ※  
* finally は例外を飲み込まない
* finally 内で例外が発生すると、もともと発生した例外が失われる
* finally 内で例外が発生しそうな場合は注意が必要
```C#
try
{
    throw new InvalidOperationException("元の例外");
}
finally
{
    throw new Exception("finallyで発生した例外"); // 元の例外が消える
}
```

## 例外のスロー
```C#
if (value < 0)
{
    throw new ArgumentOutOfRangeException("value", "値は0以上でなければなりません。");
}
```

## 例外の再スロー
### throwをそのまま使う
例外の元のスタックトレースを保持して再スローする
```C#
catch (Exception ex)
{
    // ログなどの処理
    Console.WriteLine("例外を記録: " + ex.Message);
    throw; // 元のスタックトレースを保持して再スロー
}
```

### 新しい例外をスローする
元のスタックトレースは失われるが、カスタマイズしたメッセージや処理が可能
```C#
catch (Exception ex)
{
    throw new Exception("カスタムメッセージ", ex); // 内部例外として元の例外を保持
}
```

### ユーザー定義の例外
```C#
public class CustomException : Exception
{
    public CustomException(string message) : base(message) { }
}

// 使用例
throw new CustomException("カスタム例外が発生しました。");
```

### 例外フィルター
C#では`when`キーワードを使って、`catch`ブロックに条件を追加できる  
これにより、特定の条件に基づいて例外を処理することが可能
```C#
catch (Exception ex) when (ex.Message.Contains("特定のエラー"))
{
    Console.WriteLine("特定のエラーが発生しました。");
}
```

## 例外処理の種類
* `System.Exception`：すべての例外の基底クラス
* `System.SystemException`：一般的なシステムエラーに対応する例外を含む
* `System.IO.IOException`：入出力操作関連の例外を含む
* `System.Runtime.InteropServices.ExternalException`：外部コンポーネントやWindows APIとの連携中の例外

### 例外とエラーの継承関係
```
System.Exception
├── System.SystemException (基本的なシステム例外)
│   ├── System.OutOfMemoryException【ヒープ領域が不足】※ 通常キャッチできない。場合によっては余地がなく、プロセスが終了する
│   ├── System.StackOverflowException【無限再帰などでスタック限界超過】※ 通常キャッチできない。場合によっては余地がなく、プロセスが終了する
│   ├── System.IndexOutOfRangeException【配列やコレクションのインデックス範囲外】
│   ├── System.NullReferenceException【null参照へのアクセス】
│   ├── System.InvalidOperationException【操作がオブジェクトの現在の状態で無効】
│   ├── System.ArgumentException【無効な引数】
│   │   ├── System.ArgumentNullException【nullが渡された】
│   │   └── System.ArgumentOutOfRangeException【引数が許容範囲外】
│   ├── System.DivideByZeroException【0での除算】
│   ├── System.FormatException【文字列の解析エラー（例: 数値変換失敗）】
│   ├── System.NotSupportedException【サポートされていない操作】
│   ├── System.OverflowException【演算でのオーバーフロー】
│   ├── System.TypeInitializationException【型の初期化に失敗】
│   └── System.UnauthorizedAccessException【リソースへのアクセスが許可されていない】
│
├── System.IO.IOException (入出力例外)
│   ├── System.IO.FileNotFoundException【ファイルが見つからない】
│   ├── System.IO.DirectoryNotFoundException【ディレクトリが見つからない】
│   ├── System.IO.EndOfStreamException【ストリームの終端に到達】
│   ├── System.IO.PathTooLongException【パス名が長すぎる】
│   └── System.IO.DriveNotFoundException【ドライブが見つからない】
│
├── System.Threading.ThreadAbortException【スレッドの中止】
├── System.Threading.Tasks.TaskCanceledException【タスクがキャンセルされた】
├── System.InvalidCastException【無効な型キャスト】
├── System.NotImplementedException【未実装のメソッド】
├── System.Security.SecurityException【セキュリティ違反】
├── System.Data.DataException (データ操作関連)
│   ├── System.Data.SqlClient.SqlException【SQL関連の例外】
│   └── System.Data.ConstraintException【データベース制約違反】
│
└── System.Runtime.InteropServices.ExternalException (外部エラー)
    ├── System.Runtime.InteropServices.COMException【COM関連のエラー】
    ├── System.Runtime.InteropServices.SEHException【構造化例外処理のエラー】
    └── System.ComponentModel.Win32Exception【Windows API呼び出しエラー】
```

## 例外処理のベストプラクティス
* 具体的な例外をキャッチする
  * `Exception`を直接キャッチするのは避け、特定の例外を明示的にキャッチする
```C#
catch (FileNotFoundException ex) { ... }
catch (UnauthorizedAccessException ex) { ... }
```
* 例外を過度にキャッチしない  
  * 必要のない場合に例外をキャッチして無視するのは非推奨
  * 例外はシステムの異常状態を知らせるためのもの
* 例外メッセージをユーザー向けに隠蔽する
  * ユーザーにシステム内部の情報を表示しないようにする（セキュリティリスク）
* パフォーマンスを考慮
  * 例外は通常の制御フローとして使用しない
  * 例外のスローはコストが高いので、条件分岐で代替可能な場合はそうする
```C#
if (fileExists)
{
    // 正常な処理
}
else
{
    throw new FileNotFoundException("ファイルが見つかりません");
}
```

## 非同期メソッドの例外処理
非同期メソッドでは、例外は Task にラップされる  
そのため、例外を適切に処理するには、以下の方法が必要

### async メソッド内での例外
非同期メソッド内で例外が発生すると、await が例外を伝搬する
```C#
try
{
    await SomeAsyncMethod();
}
catch (Exception ex)
{
    Console.WriteLine($"非同期例外: {ex.Message}");
}
```

### Task.Wait() や Task.Result の使用
例外は AggregateException にラップされる
```C#
try
{
    Task.Run(() => { throw new InvalidOperationException("例外発生"); }).Wait();
}
catch (AggregateException aggEx)
{
    // 例外が連鎖している場合に、詳細な原因を確認するために InnerException を参照できる
    foreach (var ex in aggEx.InnerExceptions)
    {
        Console.WriteLine($"例外: {ex.Message}");
    }
}
```

## グローバル例外処理
アプリケーション全体の例外をキャッチする仕組みを導入することで、未処理例外の記録やアプリの安定性向上を図れる

### コンソールアプリの場合
```C#
AppDomain.CurrentDomain.UnhandledException += (sender, args) =>
{
    Console.WriteLine($"未処理例外: {((Exception)args.ExceptionObject).Message}");
};
```

### WPFアプリの場合
```C#
Application.Current.DispatcherUnhandledException += (sender, args) =>
{
    Console.WriteLine($"未処理例外: {args.Exception.Message}");
    args.Handled = true; // アプリの終了を防ぐ
};
```

## ロギングツールの利用
大規模なアプリケーションでは、例外の追跡と分析にログツールを使用する  
【推奨ツール】  
* NLog
* Serilog
* Log4Net

これらを利用して例外の発生状況をファイルやデータベースに記録することで、トラブルシューティングが容易になる

## 例外処理を使わない設計の検討
場合によっては、例外を使用せずエラーを戻り値やステータスコードとして処理する方法も検討できる
```C#
bool TryParseInt(string input, out int result)
{
    return int.TryParse(input, out result);
}
```
